[2023-09-15T20:16:17.822+0000] {taskinstance.py:1083} INFO - Dependencies all met for <TaskInstance: email_teste.send_email manual__2023-09-15T20:15:49.934854+00:00 [queued]>
[2023-09-15T20:16:17.832+0000] {taskinstance.py:1083} INFO - Dependencies all met for <TaskInstance: email_teste.send_email manual__2023-09-15T20:15:49.934854+00:00 [queued]>
[2023-09-15T20:16:17.832+0000] {taskinstance.py:1279} INFO - 
--------------------------------------------------------------------------------
[2023-09-15T20:16:17.833+0000] {taskinstance.py:1280} INFO - Starting attempt 2 of 2
[2023-09-15T20:16:17.833+0000] {taskinstance.py:1281} INFO - 
--------------------------------------------------------------------------------
[2023-09-15T20:16:17.850+0000] {taskinstance.py:1300} INFO - Executing <Task(EmailOperator): send_email> on 2023-09-15 20:15:49.934854+00:00
[2023-09-15T20:16:17.854+0000] {standard_task_runner.py:55} INFO - Started process 1807 to run task
[2023-09-15T20:16:17.856+0000] {standard_task_runner.py:82} INFO - Running: ['***', 'tasks', 'run', 'email_teste', 'send_email', 'manual__2023-09-15T20:15:49.934854+00:00', '--job-id', '94', '--raw', '--subdir', 'DAGS_FOLDER/email.py', '--cfg-path', '/tmp/tmp3y1ejm_y']
[2023-09-15T20:16:17.857+0000] {standard_task_runner.py:83} INFO - Job 94: Subtask send_email
[2023-09-15T20:16:17.913+0000] {task_command.py:388} INFO - Running <TaskInstance: email_teste.send_email manual__2023-09-15T20:15:49.934854+00:00 [running]> on host 39c967e5fb3d
[2023-09-15T20:16:17.978+0000] {taskinstance.py:1509} INFO - Exporting the following env vars:
AIRFLOW_CTX_DAG_EMAIL=danilodias_lc@hotmail.com
AIRFLOW_CTX_DAG_OWNER=***
AIRFLOW_CTX_DAG_ID=email_teste
AIRFLOW_CTX_TASK_ID=send_email
AIRFLOW_CTX_EXECUTION_DATE=2023-09-15T20:15:49.934854+00:00
AIRFLOW_CTX_TRY_NUMBER=2
AIRFLOW_CTX_DAG_RUN_ID=manual__2023-09-15T20:15:49.934854+00:00
[2023-09-15T20:16:17.987+0000] {warnings.py:110} WARNING - /home/***/.local/lib/python3.7/site-packages/***/utils/email.py:152: RemovedInAirflow3Warning: Fetching SMTP credentials from configuration variables will be deprecated in a future release. Please set credentials using a connection instead.
  send_mime_email(e_from=mail_from, e_to=recipients, mime_msg=msg, conn_id=conn_id, dryrun=dryrun)

[2023-09-15T20:16:17.987+0000] {configuration.py:663} WARNING - section/key [smtp/smtp_user] not found in config
[2023-09-15T20:16:17.988+0000] {email.py:268} INFO - Email alerting: attempt 1
[2023-09-15T20:16:17.988+0000] {taskinstance.py:1768} ERROR - Task failed with exception
Traceback (most recent call last):
  File "/home/airflow/.local/lib/python3.7/site-packages/airflow/operators/email.py", line 87, in execute
    custom_headers=self.custom_headers,
  File "/home/airflow/.local/lib/python3.7/site-packages/airflow/utils/email.py", line 91, in send_email
    **kwargs,
  File "/home/airflow/.local/lib/python3.7/site-packages/airflow/utils/email.py", line 152, in send_email_smtp
    send_mime_email(e_from=mail_from, e_to=recipients, mime_msg=msg, conn_id=conn_id, dryrun=dryrun)
  File "/home/airflow/.local/lib/python3.7/site-packages/airflow/utils/email.py", line 270, in send_mime_email
    smtp_conn = _get_smtp_connection(smtp_host, smtp_port, smtp_timeout, smtp_ssl)
  File "/home/airflow/.local/lib/python3.7/site-packages/airflow/utils/email.py", line 317, in _get_smtp_connection
    else smtplib.SMTP(host=host, port=port, timeout=timeout)
  File "/usr/local/lib/python3.7/smtplib.py", line 251, in __init__
    (code, msg) = self.connect(host, port)
  File "/usr/local/lib/python3.7/smtplib.py", line 336, in connect
    self.sock = self._get_socket(host, port, self.timeout)
  File "/usr/local/lib/python3.7/smtplib.py", line 307, in _get_socket
    self.source_address)
  File "/usr/local/lib/python3.7/socket.py", line 728, in create_connection
    raise err
  File "/usr/local/lib/python3.7/socket.py", line 716, in create_connection
    sock.connect(sa)
OSError: [Errno 99] Cannot assign requested address
[2023-09-15T20:16:17.995+0000] {taskinstance.py:1323} INFO - Marking task as FAILED. dag_id=email_teste, task_id=send_email, execution_date=20230915T201549, start_date=20230915T201617, end_date=20230915T201617
[2023-09-15T20:16:18.005+0000] {configuration.py:663} WARNING - section/key [smtp/smtp_user] not found in config
[2023-09-15T20:16:18.005+0000] {email.py:268} INFO - Email alerting: attempt 1
[2023-09-15T20:16:18.011+0000] {configuration.py:663} WARNING - section/key [smtp/smtp_user] not found in config
[2023-09-15T20:16:18.011+0000] {email.py:268} INFO - Email alerting: attempt 1
[2023-09-15T20:16:18.012+0000] {taskinstance.py:1831} ERROR - Failed to send email to: ['danilodias_lc@hotmail.com']
Traceback (most recent call last):
  File "/home/airflow/.local/lib/python3.7/site-packages/airflow/models/taskinstance.py", line 1374, in _run_raw_task
    self._execute_task_with_callbacks(context, test_mode)
  File "/home/airflow/.local/lib/python3.7/site-packages/airflow/models/taskinstance.py", line 1520, in _execute_task_with_callbacks
    result = self._execute_task(context, task_orig)
  File "/home/airflow/.local/lib/python3.7/site-packages/airflow/models/taskinstance.py", line 1581, in _execute_task
    result = execute_callable(context=context)
  File "/home/airflow/.local/lib/python3.7/site-packages/airflow/operators/email.py", line 87, in execute
    custom_headers=self.custom_headers,
  File "/home/airflow/.local/lib/python3.7/site-packages/airflow/utils/email.py", line 91, in send_email
    **kwargs,
  File "/home/airflow/.local/lib/python3.7/site-packages/airflow/utils/email.py", line 152, in send_email_smtp
    send_mime_email(e_from=mail_from, e_to=recipients, mime_msg=msg, conn_id=conn_id, dryrun=dryrun)
  File "/home/airflow/.local/lib/python3.7/site-packages/airflow/utils/email.py", line 270, in send_mime_email
    smtp_conn = _get_smtp_connection(smtp_host, smtp_port, smtp_timeout, smtp_ssl)
  File "/home/airflow/.local/lib/python3.7/site-packages/airflow/utils/email.py", line 317, in _get_smtp_connection
    else smtplib.SMTP(host=host, port=port, timeout=timeout)
  File "/usr/local/lib/python3.7/smtplib.py", line 251, in __init__
    (code, msg) = self.connect(host, port)
  File "/usr/local/lib/python3.7/smtplib.py", line 336, in connect
    self.sock = self._get_socket(host, port, self.timeout)
  File "/usr/local/lib/python3.7/smtplib.py", line 307, in _get_socket
    self.source_address)
  File "/usr/local/lib/python3.7/socket.py", line 728, in create_connection
    raise err
  File "/usr/local/lib/python3.7/socket.py", line 716, in create_connection
    sock.connect(sa)
OSError: [Errno 99] Cannot assign requested address

During handling of the above exception, another exception occurred:

Traceback (most recent call last):
  File "/home/airflow/.local/lib/python3.7/site-packages/airflow/models/taskinstance.py", line 2231, in email_alert
    send_email(task.email, subject, html_content)
  File "/home/airflow/.local/lib/python3.7/site-packages/airflow/utils/email.py", line 91, in send_email
    **kwargs,
  File "/home/airflow/.local/lib/python3.7/site-packages/airflow/utils/email.py", line 152, in send_email_smtp
    send_mime_email(e_from=mail_from, e_to=recipients, mime_msg=msg, conn_id=conn_id, dryrun=dryrun)
  File "/home/airflow/.local/lib/python3.7/site-packages/airflow/utils/email.py", line 270, in send_mime_email
    smtp_conn = _get_smtp_connection(smtp_host, smtp_port, smtp_timeout, smtp_ssl)
  File "/home/airflow/.local/lib/python3.7/site-packages/airflow/utils/email.py", line 317, in _get_smtp_connection
    else smtplib.SMTP(host=host, port=port, timeout=timeout)
  File "/usr/local/lib/python3.7/smtplib.py", line 251, in __init__
    (code, msg) = self.connect(host, port)
  File "/usr/local/lib/python3.7/smtplib.py", line 336, in connect
    self.sock = self._get_socket(host, port, self.timeout)
  File "/usr/local/lib/python3.7/smtplib.py", line 307, in _get_socket
    self.source_address)
  File "/usr/local/lib/python3.7/socket.py", line 728, in create_connection
    raise err
  File "/usr/local/lib/python3.7/socket.py", line 716, in create_connection
    sock.connect(sa)
OSError: [Errno 99] Cannot assign requested address

During handling of the above exception, another exception occurred:

Traceback (most recent call last):
  File "/home/airflow/.local/lib/python3.7/site-packages/airflow/models/taskinstance.py", line 1829, in handle_failure
    self.email_alert(error, task)
  File "/home/airflow/.local/lib/python3.7/site-packages/airflow/models/taskinstance.py", line 2233, in email_alert
    send_email(task.email, subject, html_content_err)
  File "/home/airflow/.local/lib/python3.7/site-packages/airflow/utils/email.py", line 91, in send_email
    **kwargs,
  File "/home/airflow/.local/lib/python3.7/site-packages/airflow/utils/email.py", line 152, in send_email_smtp
    send_mime_email(e_from=mail_from, e_to=recipients, mime_msg=msg, conn_id=conn_id, dryrun=dryrun)
  File "/home/airflow/.local/lib/python3.7/site-packages/airflow/utils/email.py", line 270, in send_mime_email
    smtp_conn = _get_smtp_connection(smtp_host, smtp_port, smtp_timeout, smtp_ssl)
  File "/home/airflow/.local/lib/python3.7/site-packages/airflow/utils/email.py", line 317, in _get_smtp_connection
    else smtplib.SMTP(host=host, port=port, timeout=timeout)
  File "/usr/local/lib/python3.7/smtplib.py", line 251, in __init__
    (code, msg) = self.connect(host, port)
  File "/usr/local/lib/python3.7/smtplib.py", line 336, in connect
    self.sock = self._get_socket(host, port, self.timeout)
  File "/usr/local/lib/python3.7/smtplib.py", line 307, in _get_socket
    self.source_address)
  File "/usr/local/lib/python3.7/socket.py", line 728, in create_connection
    raise err
  File "/usr/local/lib/python3.7/socket.py", line 716, in create_connection
    sock.connect(sa)
OSError: [Errno 99] Cannot assign requested address
[2023-09-15T20:16:18.028+0000] {standard_task_runner.py:105} ERROR - Failed to execute job 94 for task send_email ([Errno 99] Cannot assign requested address; 1807)
[2023-09-15T20:16:18.068+0000] {local_task_job.py:208} INFO - Task exited with return code 1
[2023-09-15T20:16:18.085+0000] {taskinstance.py:2578} INFO - 0 downstream tasks scheduled from follow-on schedule check
